#VRML_SIM R2023b utf8

EXTERNPROTO "https://raw.githubusercontent.com/cyberbotics/webots/R2023b/projects/appearances/protos/BrushedSteel.proto"
EXTERNPROTO "https://raw.githubusercontent.com/cyberbotics/webots/R2023b/projects/appearances/protos/Copper.proto"
EXTERNPROTO "https://raw.githubusercontent.com/cyberbotics/webots/R2023b/projects/appearances/protos/DamascusSteel.proto"
EXTERNPROTO "https://raw.githubusercontent.com/cyberbotics/webots/R2023b/projects/appearances/protos/DryMud.proto"
EXTERNPROTO "https://raw.githubusercontent.com/cyberbotics/webots/R2023b/projects/appearances/protos/HammeredCopper.proto"
EXTERNPROTO "https://raw.githubusercontent.com/cyberbotics/webots/R2023b/projects/appearances/protos/ReflectiveSurface.proto"
EXTERNPROTO "https://raw.githubusercontent.com/cyberbotics/webots/R2023b/projects/appearances/protos/RoughPolymer.proto"
EXTERNPROTO "https://raw.githubusercontent.com/cyberbotics/webots/R2023b/projects/appearances/protos/SandyGround.proto"
EXTERNPROTO "https://raw.githubusercontent.com/cyberbotics/webots/R2023b/projects/appearances/protos/SolarCell.proto"
EXTERNPROTO "https://raw.githubusercontent.com/cyberbotics/webots/R2023b/projects/objects/backgrounds/protos/TexturedBackground.proto"
EXTERNPROTO "https://raw.githubusercontent.com/cyberbotics/webots/R2023b/projects/objects/backgrounds/protos/TexturedBackgroundLight.proto"
EXTERNPROTO "https://raw.githubusercontent.com/cyberbotics/webots/R2023b/projects/objects/floors/protos/UnevenTerrain.proto"

WorldInfo {
}
Viewpoint {
  orientation 0.32452290765153463 -0.5628520622180568 -0.7601857920707769 5.078634320437011
  position -4.240887594173124 -11.209958944245779 8.405696466681196
}
TexturedBackground {
  texture "mars"
}
TexturedBackgroundLight {
  luminosity 2
}
UnevenTerrain {
  translation 0 0 -4.44
  appearance SandyGround {
    colorOverride 0.55 0.55 0.4
    textureTransform TextureTransform {
      scale 50 50
    }
  }
}
Solid {
  translation 4.484600194477621 -5.268480399117916 -0.7957192253888741
  rotation 0.3886199586413521 0.6064341268562108 0.6936945851956313 2.3737718132255297
  children [
    DEF box Shape {
      appearance DryMud {
      }
      geometry Box {
        size 1 1.5 2
      }
    }
  ]
  name "solid(2)"
  boundingObject USE box
  physics DEF phy1 Physics {
    mass 1
  }
  linearVelocity -4.314527815430093e-06 -3.8748516205776945e-06 1.328724369373168e-06
  angularVelocity -6.022366294461182e-07 -6.049299744058283e-07 -4.021924960590448e-07
}
Solid {
  translation 1.0157919055902491 -0.746827419081996 -0.5074261961746238
  rotation 0.9993526970267972 -0.031874669921543426 0.01667909957578372 1.646730307178741
  children [
    DEF box Shape {
      appearance DryMud {
      }
      geometry Box {
        size 0.8 1.7 0.9
      }
    }
  ]
  name "solid(4)"
  boundingObject USE box
  physics USE phy1
  linearVelocity -1.2330953685322226e-06 -1.8236746543141005e-06 -1.9779892033966462e-07
  angularVelocity 1.190688969235945e-08 1.3980971000372643e-09 -3.242487624570154e-08
}
Solid {
  translation 1.158524181422228 -3.287101169813023 -1.1240123876413217
  rotation 0.8812697086650112 -0.3395744817412761 -0.3287139667547306 1.8251204836559067
  children [
    DEF box Shape {
      appearance DryMud {
      }
      geometry Box {
        size 1.5 0.9 0.9
      }
    }
  ]
  name "solid(1)"
  boundingObject USE box
  physics DEF phy1 Physics {
    mass 1
  }
  linearVelocity -2.4248015638812504e-06 -4.7081390275434674e-06 -6.108107046998157e-07
  angularVelocity 1.0923670406622985e-08 -2.5459673666036495e-08 3.034331788767633e-07
}
Robot {
  translation 3.8195818566651285 -1.5882325480130568 -0.9626896114713042
  rotation 0.21555618459209813 -0.14614577210812066 -0.9654931095450752 0.4272419888656179
  children [
    DEF body Shape {
      appearance HammeredCopper {
      }
      geometry Box {
        size 0.7 0.5 0.2
      }
    }
    DistanceSensor {
      translation -0.35 -0.14 0
      rotation 0 0 1 -2.5
      children [
        DEF ds Shape {
          appearance ReflectiveSurface {
          }
          geometry Box {
            size 0.05 0.05 0.05
          }
        }
      ]
      name "ds1"
      boundingObject USE ds
      physics Physics {
        mass 1
      }
      translationStep 0.11
      lookupTable [
        0 0 0
        1 1000 0
      ]
      aperture 1.5715
    }
    DistanceSensor {
      translation -0.35 0.15 0
      rotation 0 0 1 2.6763956132800115
      children [
        DEF ds2 Shape {
          appearance ReflectiveSurface {
          }
          geometry Box {
            size 0.05 0.05 0.05
          }
        }
      ]
      name "ds2"
      boundingObject USE ds2
      physics Physics {
        mass 1
      }
      lookupTable [
        0 0 0
        1 1000 0
      ]
    }
    Solid {
      translation 0.03 0 0.19
      children [
        DEF panel Shape {
          appearance SolarCell {
          }
          geometry Box {
            size 0.6 0.5 0.01
          }
        }
        Solid {
          translation 0.25 -0.19 -0.05
          children [
            Shape {
              appearance Copper {
              }
              geometry Cylinder {
                height 0.1
                radius 0.02
              }
            }
          ]
          name "solar_panel_support1"
        }
        Solid {
          translation 0.25 0.19 -0.05
          children [
            Shape {
              appearance Copper {
              }
              geometry Cylinder {
                height 0.1
                radius 0.02
              }
            }
          ]
          name "solar_panel_support2"
        }
        Solid {
          translation -0.25 0.19 -0.05
          children [
            Shape {
              appearance Copper {
              }
              geometry Cylinder {
                height 0.1
                radius 0.02
              }
            }
          ]
          name "solar_panel_support3"
        }
        Solid {
          translation -0.25 -0.19 -0.05
          children [
            Shape {
              appearance Copper {
              }
              geometry Cylinder {
                height 0.1
                radius 0.02
              }
            }
          ]
          name "solar_panel_support4"
        }
      ]
      name "solar_panel"
    }
    Solid {
      translation -0.18 -0.24 0
      children [
        Solid {
          translation -0.00017766252744422228 -0.017340268664742475 0.05993637531167906
          rotation -0.9999999929357695 8.124469320562993e-05 -8.676267159571073e-05 1.5708626067521982
          children [
            DEF cylinder1 Shape {
              appearance DamascusSteel {
              }
              geometry Cylinder {
                height 0.09
                radius 0.02
              }
            }
            Solid {
              translation 0 0 -0.05
              children [
                DEF sphere1 Shape {
                  appearance BrushedSteel {
                  }
                  geometry Sphere {
                    radius 0.02
                  }
                }
                Solid {
                  translation 0 0.1 1.79608e-07
                  rotation -1 0 0 -1.5707953071795862
                  children [
                    DEF cylinder2 Shape {
                      appearance BrushedSteel {
                      }
                      geometry Cylinder {
                        height 0.2
                        radius 0.02
                      }
                    }
                    Solid {
                      translation 0 0 -0.11
                      children [
                        DEF sphere1 Shape {
                          appearance BrushedSteel {
                          }
                          geometry Sphere {
                            radius 0.02
                          }
                        }
                        Solid {
                          translation 0 -0.03 -9.99999e-08
                          rotation 1 0 0 1.5708
                          children [
                            DEF cylinder3 Shape {
                              appearance BrushedSteel {
                              }
                              geometry Cylinder {
                                height 0.06
                                radius 0.02
                              }
                            }
                            HingeJoint {
                              jointParameters HingeJointParameters {
                                position 386.72724079396056
                                axis 0 0 1
                                anchor -9.51224e-05 0.00113507 0.0800056
                              }
                              device [
                                RotationalMotor {
                                  name "wheel1_left"
                                }
                              ]
                              endPoint Solid {
                                translation -0.001588101931982897 0.001903736265966221 0.07994157767599397
                                rotation -5.7800418227723365e-06 -9.757275788893536e-07 -0.9999999999828196 2.8183688238103315
                                children [
                                  DEF wheel Shape {
                                    appearance DamascusSteel {
                                    }
                                    geometry Cylinder {
                                      height 0.15
                                      radius 0.15
                                    }
                                  }
                                ]
                                boundingObject USE wheel
                                physics Physics {
                                  mass 1
                                }
                                linearVelocity -2.362198618183698e-05 -3.526218577528793e-05 -4.612783005484392e-06
                                angularVelocity -4.44345458593259e-07 -1.6604151534117809e-06 9.845969032876232e-06
                              }
                            }
                          ]
                          boundingObject USE cylinder3
                          physics DEF phy1 Physics {
                            mass 1
                          }
                        }
                      ]
                      name "solid(1)"
                      boundingObject USE sphere1
                      physics USE phy1
                    }
                  ]
                  boundingObject USE cylinder2
                  physics USE phy1
                }
              ]
              boundingObject USE sphere1
              physics USE phy1
            }
          ]
          boundingObject USE cylinder1
          physics USE phy1
        }
      ]
      name "wheel1_left_system"
      physics DEF phy1 Physics {
        mass 1
      }
    }
    Solid {
      translation 0.18 -0.24 0
      children [
        Solid {
          translation -0.0001757815149209252 -0.017333744024692788 0.0600545153188472
          rotation -0.9999999930027248 7.374603208071159e-05 -9.249904417794078e-05 1.5708786387286822
          children [
            DEF cylinder1 Shape {
              appearance DamascusSteel {
              }
              geometry Cylinder {
                height 0.09
                radius 0.02
              }
            }
            Solid {
              translation 0 0 -0.05
              children [
                DEF sphere1 Shape {
                  appearance BrushedSteel {
                  }
                  geometry Sphere {
                    radius 0.02
                  }
                }
                Solid {
                  translation 0 0.1 1.79608e-07
                  rotation -1 0 0 -1.5707953071795862
                  children [
                    DEF cylinder2 Shape {
                      appearance BrushedSteel {
                      }
                      geometry Cylinder {
                        height 0.2
                        radius 0.02
                      }
                    }
                    Solid {
                      translation 0 0 -0.11
                      children [
                        DEF sphere1 Shape {
                          appearance BrushedSteel {
                          }
                          geometry Sphere {
                            radius 0.02
                          }
                        }
                        Solid {
                          translation 0 -0.03 -9.99999e-08
                          rotation 1 0 0 1.5708
                          children [
                            DEF cylinder3 Shape {
                              appearance BrushedSteel {
                              }
                              geometry Cylinder {
                                height 0.06
                                radius 0.02
                              }
                            }
                            HingeJoint {
                              jointParameters HingeJointParameters {
                                position 80.05810980679901
                                axis 0 0 1
                                anchor 0.000341778 0.000558794 0.0800055
                              }
                              device [
                                RotationalMotor {
                                  name "wheel2_left"
                                }
                              ]
                              endPoint Solid {
                                translation -0.00027873702264815406 0.000965871112263961 0.07993867002042876
                                rotation -1.5273554111103927e-06 1.5136305025665015e-06 -0.999999999997688 1.6125450283330613
                                children [
                                  DEF wheel Shape {
                                    appearance DamascusSteel {
                                    }
                                    geometry Cylinder {
                                      height 0.15
                                      radius 0.15
                                    }
                                  }
                                ]
                                boundingObject USE wheel
                                physics Physics {
                                  mass 1
                                }
                                linearVelocity -2.2195826242715068e-05 -3.1984868674644624e-05 -4.225396199501575e-06
                                angularVelocity -9.484615833185777e-07 -2.8172986662909657e-06 9.716673284735969e-06
                              }
                            }
                          ]
                          boundingObject USE cylinder3
                          physics DEF phy1 Physics {
                            mass 1
                          }
                        }
                      ]
                      name "solid(1)"
                      boundingObject USE sphere1
                      physics USE phy1
                    }
                  ]
                  boundingObject USE cylinder2
                  physics USE phy1
                }
              ]
              boundingObject USE sphere1
              physics USE phy1
            }
          ]
          boundingObject USE cylinder1
          physics USE phy1
        }
      ]
      name "wheel2_left_system"
      physics USE phy1
    }
    Solid {
      translation -0.18 0.24 0
      children [
        Solid {
          translation -0.000177663 0.0173403 0.0599364
          rotation -0.9999999929357695 8.124469320562993e-05 -8.676267159571073e-05 1.5708626067521982
          children [
            DEF cylinder1 Shape {
              appearance DamascusSteel {
              }
              geometry Cylinder {
                height 0.09
                radius 0.02
              }
            }
            Solid {
              translation 0 0 0.05
              children [
                DEF sphere1 Shape {
                  appearance BrushedSteel {
                  }
                  geometry Sphere {
                    radius 0.02
                  }
                }
                Solid {
                  translation 0 0.1 1.79608e-07
                  rotation -1 0 0 -1.5707953071795862
                  children [
                    DEF cylinder2 Shape {
                      appearance BrushedSteel {
                      }
                      geometry Cylinder {
                        height 0.2
                        radius 0.02
                      }
                    }
                    Solid {
                      translation 0 0 -0.11
                      children [
                        DEF sphere1 Shape {
                          appearance BrushedSteel {
                          }
                          geometry Sphere {
                            radius 0.02
                          }
                        }
                        Solid {
                          translation 0 0.03 -9.99999e-08
                          rotation 1 0 0 1.5708
                          children [
                            DEF cylinder3 Shape {
                              appearance BrushedSteel {
                              }
                              geometry Cylinder {
                                height 0.06
                                radius 0.02
                              }
                            }
                            HingeJoint {
                              jointParameters HingeJointParameters {
                                position 401.37119025213156
                                axis 0 0 1
                                anchor 0.00237208 0.000614304 -0.0799754
                              }
                              device [
                                RotationalMotor {
                                  name "wheel1_right"
                                }
                              ]
                              endPoint Solid {
                                translation 0.0005927409655659441 0.0009623240976090699 -0.07999019576394151
                                rotation -0.381587796502101 0.9243325989693757 -6.571964142479735e-06 3.1415924804810165
                                children [
                                  DEF wheel Shape {
                                    appearance DamascusSteel {
                                    }
                                    geometry Cylinder {
                                      height 0.15
                                      radius 0.15
                                    }
                                  }
                                ]
                                boundingObject USE wheel
                                physics Physics {
                                  mass 1
                                }
                                linearVelocity -3.1249143839488665e-05 -3.1938687879652244e-05 -4.40172024121913e-06
                                angularVelocity -1.4671809773686696e-06 -4.007698402992638e-06 9.583572095032412e-06
                              }
                            }
                          ]
                          boundingObject USE cylinder3
                          physics DEF phy1 Physics {
                            mass 1
                          }
                        }
                      ]
                      name "solid(1)"
                      boundingObject USE sphere1
                      physics USE phy1
                    }
                  ]
                  boundingObject USE cylinder2
                  physics USE phy1
                }
              ]
              boundingObject USE sphere1
              physics USE phy1
            }
          ]
          boundingObject USE cylinder1
          physics USE phy1
        }
      ]
      name "wheel1_right_system"
      physics DEF phy1 Physics {
        mass 1
      }
    }
    Solid {
      translation 0.18 0.24 0
      children [
        Solid {
          translation -0.000177663 0.0173403 0.0599364
          rotation -0.9999999929357695 8.124469320562993e-05 -8.676267159571073e-05 1.5708626067521982
          children [
            DEF cylinder1 Shape {
              appearance DamascusSteel {
              }
              geometry Cylinder {
                height 0.09
                radius 0.02
              }
            }
            Solid {
              translation 0 0 0.05
              children [
                DEF sphere1 Shape {
                  appearance BrushedSteel {
                  }
                  geometry Sphere {
                    radius 0.02
                  }
                }
                Solid {
                  translation 0 0.1 1.79608e-07
                  rotation -1 0 0 -1.5707953071795862
                  children [
                    DEF cylinder2 Shape {
                      appearance BrushedSteel {
                      }
                      geometry Cylinder {
                        height 0.2
                        radius 0.02
                      }
                    }
                    Solid {
                      translation 0 0 -0.11
                      children [
                        DEF sphere1 Shape {
                          appearance BrushedSteel {
                          }
                          geometry Sphere {
                            radius 0.02
                          }
                        }
                        Solid {
                          translation 0 0.03 -9.99999e-08
                          rotation 1 0 0 1.5708
                          children [
                            DEF cylinder3 Shape {
                              appearance BrushedSteel {
                              }
                              geometry Cylinder {
                                height 0.06
                                radius 0.02
                              }
                            }
                            HingeJoint {
                              jointParameters HingeJointParameters {
                                position 402.92918391962206
                                axis 0 0 1
                                anchor 0.00237208 0.000614304 -0.0799754
                              }
                              device [
                                RotationalMotor {
                                  name "wheel2_right"
                                }
                              ]
                              endPoint Solid {
                                translation 0.0017787275118882622 -0.0009489692097677587 -0.07998820342901869
                                rotation 0.9209496793651459 -0.3896815213275092 3.621167490258202e-06 3.1416012354574976
                                children [
                                  DEF wheel Shape {
                                    appearance DamascusSteel {
                                    }
                                    geometry Cylinder {
                                      height 0.15
                                      radius 0.15
                                    }
                                  }
                                ]
                                boundingObject USE wheel
                                physics Physics {
                                  mass 1
                                }
                                linearVelocity -2.9815799587332504e-05 -2.8665346477950545e-05 -4.0121463520676945e-06
                                angularVelocity -1.9061418742893891e-06 -5.015052258197191e-06 9.470963384762497e-06
                              }
                            }
                          ]
                          boundingObject USE cylinder3
                          physics DEF phy1 Physics {
                            mass 1
                          }
                        }
                      ]
                      name "solid(1)"
                      boundingObject USE sphere1
                      physics USE phy1
                    }
                  ]
                  boundingObject USE cylinder2
                  physics USE phy1
                }
              ]
              boundingObject USE sphere1
              physics USE phy1
            }
          ]
          boundingObject USE cylinder1
          physics USE phy1
        }
      ]
      name "wheel2_right_system"
      physics DEF phy1 Physics {
        mass 1
      }
    }
    Solid {
      translation -0.3 0 0.4
      children [
        DEF camStand Shape {
          appearance Copper {
          }
          geometry Cylinder {
            height 0.6
            radius 0.02
          }
        }
        SliderJoint {
          jointParameters JointParameters {
            position 0.2699414986637186
            minStop -0.3
            maxStop 0.3
            dampingConstant 1
            staticFriction 3
          }
          device [
            LinearMotor {
              name "cam_slider"
            }
          ]
          endPoint Solid {
            translation -2.9551326349519513e-05 -1.991890490060655e-05 0.26993330606146243
            rotation -3.0884260299697183e-06 -2.9264584594029586e-07 0.9999999999951881 -3.141585063926957
            children [
              DEF box1 Shape {
                appearance RoughPolymer {
                }
                geometry Box {
                  size 0.05 0.05 0.05
                }
              }
              Camera {
              }
            ]
            boundingObject USE box1
            physics USE phy1
            linearVelocity -2.8168374447172496e-05 -3.516848373648012e-05 -4.690390209248107e-06
            angularVelocity -1.9429249261688188e-07 -1.086700339898081e-06 9.910108147962782e-06
          }
        }
      ]
      name "camStand"
      boundingObject USE camStand
      physics USE phy1
    }
  ]
  boundingObject USE body
  physics DEF phy Physics {
    mass 1
  }
  controller "robo_controller"
  linearVelocity -2.6908661122422304e-05 -3.236404753085143e-05 -4.358169931362811e-06
  angularVelocity -1.9429148734271993e-07 -1.0866946220549651e-06 9.910108137358494e-06
}
Solid {
  translation -16.983715954758853 -17.945536917809 -1.3277444000374976
  rotation 0.3562326278577925 0.6892702995057194 0.6308761915533247 2.545069162806284
  children [
    DEF box Shape {
      appearance DryMud {
      }
      geometry Box {
        size 2.5 2 0.4
      }
    }
  ]
  boundingObject USE box
  physics USE phy1
  linearVelocity 2.778292663210279e-06 1.2670676730234536e-06 -2.695693974601454e-07
  angularVelocity -4.001164437947086e-09 -5.790223586520613e-08 -6.116801547508977e-07
}
